<?xml version="1.0"?>
<sdf version="1.7">
  <model name="bouncing_ball">
    <link name="ball">
      <pose>0 0 1 0 0 0</pose> 
      <inertial>
        <mass>1</mass>
        <inertia>
          <ixx>0.001</ixx>
          <iyy>0.001</iyy>
          <izz>0.001</izz>
          <ixy>0</ixy>
          <ixz>0</ixz>
          <iyz>0</iyz>
        </inertia>
      </inertial>
      <visual name="visual">
        <geometry>
          <sphere>
            <radius>0.1</radius>
          </sphere>
        </geometry>
        <material>
          <diffuse>1.0 0.34 0.25 1.0</diffuse>
        </material>
      </visual>
      <collision name="collision">
        <geometry>
          <sphere>
            <radius>0.1</radius>
          </sphere>
        </geometry>
        <drake:proximity_properties>
          <drake:point_contact_stiffness>
            20000
          </drake:point_contact_stiffness>
          <drake:hunt_crossley_dissipation>
            0.1
          </drake:hunt_crossley_dissipation>
        </drake:proximity_properties>
      </collision>
    </link>
    <joint name="ball_z" type="prismatic">
      <parent>world</parent>
      <child>ball</child>
      <axis>
        <xyz>0 0 1</xyz>
        <limit>
          <effort>0</effort>
        </limit>
      </axis>
    </joint>
    <link name="ground">
      <pose>0 0 -0.5 0 0 0</pose>
      <visual name="visual">
        <geometry>
          <box>
            <size>2 2 1</size>
          </box>
        </geometry>
      </visual>
      <collision name="collision">
        <geometry>
          <box>
            <size>2 2 1</size>
          </box>
        </geometry>
        <drake:proximity_properties>
          <drake:point_contact_stiffness>
            20000
          </drake:point_contact_stiffness>
          <drake:hunt_crossley_dissipation>
            0.1
          </drake:hunt_crossley_dissipation>
        </drake:proximity_properties>
      </collision>
    </link>
    <joint name="ground_weld" type="fixed">
      <parent>world</parent>
      <child>ground</child>
      <pose>0 0 0 0 0 0</pose>
    </joint>
  </model>
</sdf>