<?xml version="1.0"?>
<sdf version="1.7">
  <model name="bouncing_ball">
    <link name="ball1">
      <pose>0 0 0.05 0 0 0</pose> 
      <inertial>
        <mass>0.2460254254597445</mass>
        <inertia>
          <ixx>0.001</ixx>
          <iyy>0.001</iyy>
          <izz>0.001</izz>
          <ixy>0</ixy>
          <ixz>0</ixz>
          <iyz>0</iyz>
        </inertia>
      </inertial>
      <visual name="visual">
        <geometry>
          <mesh>
            <uri>file:///workspaces/manip-final-project/tennisball.obj</uri>
            <scale>1.0 1.0 1.0</scale>
          </mesh>
        </geometry>
        <material>
          <diffuse>1.0 0.34 0.25 1.0</diffuse>
        </material>
      </visual>
      <collision name="collision">
       <geometry>
          <mesh>
            <uri>file:///workspaces/manip-final-project/tennisball.obj</uri>
            <scale>1.0 1.0 1.0</scale>
          </mesh>
        </geometry>
        <drake:proximity_properties>
          <drake:point_contact_stiffness>
            20000
          </drake:point_contact_stiffness>
          <drake:hunt_crossley_dissipation>
            0
          </drake:hunt_crossley_dissipation>
        </drake:proximity_properties>
      </collision>
    </link>
    
    <!-- <link name="ball2">
      <pose>0 0 0.1 0 0 0</pose> 
      <inertial>
        <mass>0.2460254254597445</mass>
        <inertia>
          <ixx>0.001</ixx>
          <iyy>0.001</iyy>
          <izz>0.001</izz>
          <ixy>0</ixy>
          <ixz>0</ixz>
          <iyz>0</iyz>
        </inertia>
      </inertial>
      <visual name="visual">
        <geometry>
          <mesh>
            <uri>file:///workspaces/manip-final-project/tennisball.obj</uri>
            <scale>1.0 1.0 1.0</scale>
          </mesh>
        </geometry>
        <material>
          <diffuse>1.0 0.34 0.25 1.0</diffuse>
        </material>
      </visual>
      <collision name="collision">
       <geometry>
          <mesh>
            <uri>file:///workspaces/manip-final-project/tennisball.obj</uri>
            <scale>1.0 1.0 1.0</scale>
          </mesh>
        </geometry>
        <drake:proximity_properties>
          <drake:point_contact_stiffness>
            20000
          </drake:point_contact_stiffness>
          <drake:hunt_crossley_dissipation>
            0
          </drake:hunt_crossley_dissipation>
        </drake:proximity_properties>
      </collision>
    </link> -->
  
    <link name="bottle">
      <pose>0 0 0 0 0 0</pose>
      <inertial>
        <mass>0.10846699504413468</mass>
        <inertia>
          <ixx>0.0013346246191587629</ixx>
          <ixy>1.9282213555951406e-07</ixy>
          <ixz>-3.435531006557806e-09</ixz>
          <iyy>0.0013344123009309539</iyy>
          <iyz>-7.468889059364413e-09</iyz>
          <izz>0.00013180237893362578</izz>
        </inertia>
      </inertial>
      <visual name="visual">
        <geometry>
          <mesh>
            <uri>file:///workspaces/manip-final-project/tennisbottle.obj</uri>
            <scale>1.0 1.0 1.0</scale>
          </mesh>
        </geometry>
      </visual>
      <collision name="collision">
        <geometry>
          <mesh>
            <uri>file:///workspaces/manip-final-project/tennisbottle.obj</uri>
            <scale>1.0 1.0 1.0</scale>
          </mesh>
        </geometry>
        <drake:proximity_properties>
          <drake:point_contact_stiffness>
            20000
          </drake:point_contact_stiffness>
          <drake:hunt_crossley_dissipation>
            0
          </drake:hunt_crossley_dissipation>
        </drake:proximity_properties>
      </collision>
    </link>
    
    <joint name="ball1_z" type="prismatic">
      <parent>bottle</parent>
      <child>ball1</child>
      <axis>
        <xyz>0 0 1</xyz>
        <limit>
          <lower>0</lower>
          <upper>0.16</upper>
        </limit>
      </axis>
    </joint>
    
    <!-- <joint name="ball2_z" type="prismatic">
      <parent>bottle</parent>
      <child>ball2</child>
      <axis>
        <xyz>0 0 1</xyz>
        <limit>
          <lower>0</lower>
          <upper>0.16</upper>
        </limit>
      </axis>
    </joint> -->

    <link name="table">
      <inertial>
        <mass>18.70</mass>
        <inertia>
          <ixx>0.79</ixx>
          <ixy>0</ixy>
          <ixz>0</ixz>
          <iyy>0.53</iyy>
          <iyz>0</iyz>
          <izz>1.2</izz>
        </inertia>
      </inertial>
    <visual name="bottom">
        <pose>0.0 0.0 0 0 0 0</pose>
        <geometry>
          <box>
            <size>0.49 0.63 0.015</size>
          </box>
        </geometry>
        <material>
          <diffuse>0.9 0.9 0.9 1.0</diffuse>
        </material>
      </visual>
      <collision name="bottom">
        <pose>0.0 0.0 0 0 0 0</pose>
        <geometry>
          <box>
            <size>0.49 0.63 0.015</size>
          </box>
        </geometry>
        <drake:proximity_properties>
          <drake:compliant_hydroelastic/>
          <drake:hydroelastic_modulus>1.0e6</drake:hydroelastic_modulus>
        </drake:proximity_properties>
      </collision>
    </link>
    
    <joint name="ground_weld" type="fixed">
      <parent>world</parent>
      <child>table</child>
      <pose>0 0 0 0 0 0</pose>
    </joint>
  </model>
</sdf>